Workbook

Sheet VA Strategic Goals 
A1: Goal 1
B2: VA will consistently communicate with our customers and partners to assess and maximize performance, evaluate needs and build long-term relationships and trust
A3: Goal 2
B4: VA will deliver timely, accessible and high-quality benefits, care and services to meet the unique needs of Veterans and all those we serve
A5: Goal 3
B6: VA will build and maintain trust with Veterans, their families, caregivers and survivors—as well as our employees and partners—through proven stewardship, transparency and accountability
A7: Goal 4
B8: VA will strive toward excellence in all business operations—including governance, systems, data and management—to improve experiences, satisfaction rates, accountability and security for Veterans

Sheet i Care Values
A1: Integrity:
B2: Act with high moral principle. Adhere to the highest professional standards. Maintain the trust and confidence of all with whom I engage.
A3: Commitment:
B4: Work diligently to serve Veterans and other beneficiaries. Be driven by an earnest belief in VA’s mission. Fulfill my individual responsibilities and organizational responsibilities.
A5: Advocacy:
B6: Be truly Veteran-centric by identifying, fully considering, and appropriately advancing the interests of Veterans and other beneficiaries.
A7: Respect:
B8: Treat all those I serve and with whom I work with dignity and respect. Show respect to earn it.
A9: Excellence:
B10: Strive for the highest quality and continuous improvement. Be thoughtful and decisive in leadership, accountable for my actions, willing to admit mistakes, and rigorous in correcting them.

Sheet SetUp
A2: Standards
C5: Element 1 | E5: Element 2 | G5: Element 3 | I5: Element 4
C6: Teir 1 | D6: Teir 2 | E6: Teir 1 | F6: Teir 2 | G6: Tier 1 | H6: Tier 2 | I6: Tier 1 | J6: Tier 2
B7: Standard 1 | C7: 0.1 | D7: 0.05 | E7: 95 | F7: 99 | G7: 1.5 | H7: 2 | I7: 95 | J7: 100
B8: Standard 2 | C8: 95 | D8: 100 | E8: 1 | F8: 0.5 | G8: 2 | H8: 0
B9: Standard 3 | E9: 95 | F9: 100
C10: Met | E10: Met | G10: Met | I10: Met
B11: Standard 2 | I11: 0
B12: Standard 3 | C12: 1 | G12: 1 | I12: 1
B13: Standard 4 | C13: 2 | E13: 2 | G13: 1 | I13: 1
B14: Standard 5 | C14: 1 | E14: 1 | I14: 1

Sheet Elements and Standards
A1: Element 1*
B2: Patient Care and Service
C3: Unacceptable: Any employee who does not meet the requirements to be rated Fully Successful in this Element will be rated as Unacceptable.
C4: Fully Successful: An employee is considered Fully Successful if they meet all the Tier 1 metrics for Standards 1, and 2 of this Element
C5: Exceptional: An employee is considered Exceptional if they meet all the Tier 2 metrics for Standards 1, and 2 of this Element as well as meeting at least one standard from standards 3, 4, or 5 of this Element.
D6: Standard 1
E7: Percentage of encounters which resulted in a substantiated complaint by a veteran. Tier 1 is 0.1% or less. Tier 2 is 0.05% or less
F8: Strategic Goals and Values
G9: This standard aligns with strategic goal 3 by assuring that Veterans have a positive and productive relationship with Optical shop staff centered on trust.
G10: This standard aligns with strategic goal 4 by promoting high satisfaction rates from Veterans.
G11: This standard aligns with iCare value respect by encouraging optical shop staff to treat each veteran with the utmost respect.
D12: Standard 2
E13: Participation in assigned Service Recovery efforts with documentation in notes or logs. Tier 1 is 95% or more. Tier 2 is 100%.
F14: Strategic Goals and Values
G15: This standard aligns with strategic goal 3 by assuring that Veterans have a positive and productive relationship with Optical shop staff centered on trust.
G16: This standard aligns with strategic goal 4 by promoting high satisfaction rates from Veterans.
G17: This standard aligns with iCare value Advocacy by engaging optical shop staff in service recovery when service has been below our standard of excellence.
D18: Standard 3
E19: Successfully de-escalates a challenging patient interaction without need for supervisory intervention, as documented in notes or reported by peers/supervisors.
F20: Strategic Goals and Values
G21: This standard aligns with strategic goal 2 by meeting the often unique challenges that veterans face on a daily basis.
G22: This standard aligns with strategic goal 1 by deescalating a complex situation to one where effective communication is possible.
G23: This standard aligns with iCare value Commitment when staff engage successfully with veterans who are upset or agitated rather than merely handing the veteran off to another provider or department.
D24: Standard 4
E25: Recognized by name in two or more formal commendations (e.g., STAR awards, written thank-you letters, satisfaction surveys).
F26: Strategic Goals and Values
G27: This standard aligns with strategic goal 4 by encouraging staff to strive for excellence every day.
G28: This standard aligns with strategic goal 1 as commendations and awards from Veterans demonstrate that the employee is building strong and trusting relationships with Veterans.
G29: This standard aligns with iCare value Excellence by acknowledging staff who are recognized with awards, or other recognition.
D30: Standard 5
E31: Voluntarily contributes to broader service excellence efforts (e.g., informal mentoring, sharing feedback for improvement, assisting in a service recovery beyond assigned duties).
F32: Strategic Goals and Values
G33: This standard aligns with strategic goal 2 when staff go beyond the required scope of their duties to provide care to veterans.
G34: This standard aligns with strategic goal 4 when staff provide care beyond the expectations of veterans.
G35: This standard aligns with iCare value Commitment when staff exceed what is asked of them by the VA in order to insure that veterans have the best experience possible.
A36: Element 2*
B37: Documentation
C38: Unacceptable: Any employee who does not meet the requirements to be rated Fully Successful in this Element will be rated as Unacceptable.
C39: Fully Successful: An employee is considered Fully Successful if they meet all the Tier 1 metrics for Standards 1, 2, and 3 of this Element
C40: Exceptional: An employee is considered Exceptional if they meet all the Tier 2 metrics for Standards 1, 2, and 3 of this Element as well as meeting at least one standard from standards 4 or 5 of this Element.
...

Sheet 1
C2: Element 1* | D2: Element 2* | E2: Element 3* | F2: Element 4 | H2: Key | K2: Month | L2: Element 1 Standard 1 Complaints | M2: Element 1 Standard 2 Service Recovery Missed | N2: Element 2 Standard 1 Unsigned Notes > 48 Hours | O2: Element 2 Standard 2 Exceptions | P2: Element 2 Standard 3 Non Standard Templates | Q2: Element 3 Standard 1 Encounters | R2: Element 3 Standard 2 Optician Caused Delays | S2: Element 4 Standard 1 TMS Modules Not Done | T2: TMS Modules Assigned
B3: Standard 1 | C3: =L16 -> 0.021114865 | D3: =N16 -> 100 | E3: =Q16 -> 3.5336691 | F3: =S16 -> 100 | I3: Unacceptable | K3: 10 | L3: 0 | M3: 0 | N3: 0 | O3: 0 | P3: 0 | Q3: 424 | R3: 0 | S3: 0 | T3: 0
B4: Standard 2 | C4: =M16 -> 100 | D4: =O16 -> 0.19003378 | E4: =R15 -> 0 | F4: =R34 -> 0 | I4: Minimally Successful | K4: 11 | L4: 0 | M4: 0 | N4: 0 | O4: 0 | P4: 0 | Q4: 222 | R4: 0 | S4: 0 | T4: 0
B5: Standard 3 | C5: =K34 -> 0 | D5: =P16 -> 100 | E5: =P34 -> 1 | F5: =S34 -> 0 | I5: Fully Successful | K5: 12 | L5: 0 | M5: 0 | N5: 0 | O5: 1 | P5: 0 | Q5: 498 | R5: 0 | S5: 0 | T5: 2
B6: Standard 4 | C6: =L34 -> 2 | D6: =N34 -> 3 | E6: =Q34 -> 0 | F6: =T34 -> 0 | I6: Exceptional | K6: 1 | L6: 0 | M6: 0 | N6: 0 | O6: 1 | P6: 0 | Q6: 386 | R6: 0 | S6: 0 | T6: 2
B7: Standard 5 | C7: =M34 -> 0 | D7: =O34 -> 0 | F7: =U34 -> 1 | I7: Not Fulfilled | K7: 2 | L7: 0 | M7: 0 | N7: 0 | O7: 1 | P7: 0 | Q7: 339 | R7: 0 | S7: 0 | T7: 0
B8: Standard Final | C8: =K42 -> Exceptional | D8: =L42 -> Exceptional | E8: =M42 -> Exceptional | F8: =N42 -> Exceptional | I8: Fulfilled | K8: 3 | L8: 0 | M8: 0 | N8: 0 | O8: 1 | P8: 0 | Q8: 375 | R8: 0 | S8: 0 | T8: 1
B9: Final | C9: =N44 -> OutStanding | I9: Outstanding | K9: 4 | L9: 0 | M9: 0 | N9: 0 | O9: 1 | P9: 0 | Q9: 435 | R9: 0 | S9: 0 | T9: 1
H10: * | I10: Critical Element | K10: 5 | L10: 0 | M10: 0 | N10: 0 | O10: 2 | P10: 0 | Q10: 342 | R10: 0 | S10: 0
K11: 6 | L11: 0 | M11: 0 | N11: 0 | O11: 1 | P11: 0 | Q11: 956 | R11: 0 | S11: 0
B12: Pay Period | C12: Regular | D12: OT | E12: LA | F12: LS | G12: Holiday | H12: Other | K12: 7 | L12: 1 | M12: 0 | N12: 0 | O12: 1 | P12: 0 | Q12: 759 | R12: 0 | S12: 0
B13: 20 | C13: 64 | D13: 0 | E13: 0 | F13: 0 | G13: 8 | H13: 8 | K13: 8
B14: 21 | C14: 64 | D14: 0 | E14: 0 | F14: 5.5 | G14: 0 | H14: 10.5 | K14: 9
B15: 22 | C15: 20 | D15: 0.5 | E15: 28 | F15: 13 | G15: 8 | H15: 11 | K15: Total | L15: =SUM(L3:L14) -> 1 | M15: =SUM(M3:M14) -> 0 | N15: =SUM(N3:N14) -> 0 | O15: =SUM(O3:O14) -> 9 | P15: =SUM(P3:P14) -> 0 | Q15: =SUM(Q3:Q14) -> 4736 | R15: =SUM(R3:R14) -> 0 | S15: =SUM(S3:S14) -> 0 | T15: =SUM(T3:T14) -> 6
B16: 23 | C16: 48 | D16: 0 | E16: 0 | F16: 0 | G16: 8 | H16: 24 | K16: % | L16: =SUM((L15/Q15)*100) -> 0.021114865 | M16: =SUM((1-((M15)/Q15))*100) -> 100 | N16: =SUM((1-(N15/Q15))*100) -> 100 | O16: =SUM(O15/Q15)*100 -> 0.19003378 | P16: =SUM((1-(P15/Q15))*100) -> 100 | Q16: =Q15/F47 -> 3.5336691 | S16: =SUM((1-(S15/T15))*100) -> 100
B17: 24 | C17: 74.5 | D17: 0 | E17: 0 | F17: 1.5 | G17: 0 | H17: 4 | K17: Cell | L17: C3 | M17: C4 | N17: D3 | O17: D4 | P17: D5 | Q17: E3 | R17: E4 | S17: F3
B18: 25 | C18: 55.25 | D18: 0 | E18: 0 | F18: 0 | G18: 12.75 | H18: 6
B19: 26 | C19: 64 | D19: 0 | E19: 0 | F19: 8 | G19: 8 | H19: 0 | J19: Month | K19: Element 1 Standard 3 Deescalations | L19: Element 1 Standard 4 Awards | M19: Element 1 Standard 5 Misc Vouluntary Service | N19: Element 2 Standard 4 Other staff assists | O19: Element 2 Standard 5 Process Improvement | P19: Element 3 Standard 3 Out of scope work | Q19: Element 3 Standard 4 Suggestions | R19: Element 4 Standard 2 Certifications Missing | S19: Element 4 Standard 3 New Certification | T19: Element 4 Standard 4 CE Credits | U19: Element 4 Standard 5 Voluntairy Extra Training
B20: 1 | C20: 72 | D20: 0 | E20: 0 | F20: 0 | G20: 8 | H20: 0
B21: 2 | C21: 80 | D21: 0 | E21: 0 | F21: 0 | G21: 0 | H21: 0
B22: 3 | C22: 64 | D22: 0 | E22: 0 | F22: 8 | G22: 8 | H22: 0 | J22: 10 | K22: 0 | L22: 0 | M22: 0 | N22: 0 | O22: 0 | P22: 0 | Q22: 0 | R22: 0 | S22: 0 | T22: 0 | U22: 0
B23: 4 | C23: 78.5 | D23: 0 | E23: 0 | F23: 1.5 | G23: 0 | H23: 0 | J23: 11 | K23: 0 | L23: 0 | M23: 0 | N23: 1 | O23: 0 | P23: 1 | Q23: 0 | R23: 0 | S23: 0 | T23: 0 | U23: 1
B24: 5 | C24: 80 | D24: 0 | E24: 0 | F24: 0 | G24: 0 | H24: 0 | J24: 12 | K24: 0 | L24: 1 | M24: 0 | N24: 1 | O24: 0 | P24: 0 | Q24: 0 | R24: 0 | S24: 0 | T24: 0 | U24: 0
B25: 6 | C25: 52 | D25: 0 | E25: 16 | F25: 8 | G25: 0 | H25: 4 | J25: 1 | K25: 0 | L25: 1 | M25: 0 | N25: 1 | O25: 0 | P25: 0 | Q25: 0 | R25: 0 | S25: 0 | T25: 0 | U25: 0
B26: 7 | C26: 52 | D26: 0 | E26: 0 | F26: 0 | G26: 0 | H26: 28 | J26: 2 | K26: 0 | L26: 0 | M26: 0 | N26: 0 | O26: 0 | P26: 0 | Q26: 0 | R26: 0 | S26: 0 | T26: 0 | U26: 0
B27: 8 | C27: 68 | D27: 0 | E27: 0 | F27: 0 | G27: 0 | H27: 12 | J27: 3 | K27: 0 | L27: 0 | M27: 0 | N27: 0 | O27: 0 | P27: 0 | Q27: 0 | R27: 0 | S27: 0 | T27: 0 | U27: 0
B28: 9 | C28: 64 | D28: 0 | E28: 0 | F28: 0 | G28: 0 | H28: 16 | J28: 4 | K28: 0 | L28: 0 | M28: 0 | N28: 0 | O28: 0 | P28: 0 | Q28: 0 | R28: 0 | S28: 0 | T28: 0 | U28: 0
B29: 10 | C29: 50.5 | D29: 0 | E29: 17.5 | F29: 0 | G29: 8 | H29: 4 | J29: 5 | K29: 0 | M29: 0 | N29: 0 | O29: 0 | P29: 0 | Q29: 0 | R29: 0 | S29: 0 | T29: 0 | U29: 0
B30: 11 | C30: 54.5 | D30: 0 | E30: 24 | F30: 1.5 | G30: 0 | H30: 0 | J30: 6 | K30: 0 | M30: 0 | N30: 0 | O30: 0 | P30: 0 | Q30: 0 | R30: 0 | S30: 0 | T30: 0 | U30: 0
B31: 12 | C31: 67.5 | D31: 0 | E31: 0.5 | F31: 0 | G31: 8 | H31: 4 | J31: 7 | K31: 0 | M31: 0 | N31: 0 | O31: 0 | P31: 0 | Q31: 0 | R31: 0 | S31: 0 | T31: 0 | U31: 0
B32: 13 | C32: 60 | D32: 0 | E32: 8 | F32: 0 | G32: 0 | H32: 12 | J32: 8
B33: 14 | C33: 55 | D33: 0 | E33: 5 | F33: 0 | G33: 0 | H33: 20 | J33: 9
B34: 15 | C34: 52 | D34: 0 | E34: 12 | F34: 0 | G34: 0 | H34: 16 | J34: Total | K34: =SUM(K22:K33) -> 0 | L34: =SUM(L22:L33) -> 2 | M34: =SUM(M22:M33) -> 0 | N34: =SUM(N22:N33) -> 3 | O34: =SUM(O22:O33) -> 0 | P34: =SUM(P22:P33) -> 1 | Q34: =SUM(Q22:Q33) -> 0 | R34: =SUM(R22:R33) -> 0 | ... U34: =SUM(U22:U33) -> 1
B35: 16 | J35: Cell | K35: C5 | L35: C6 | M35: C7 | N35: D6 | O35: D7 | P35: E5 | Q35: E6 | R35: F4 | S35: F5 | T35: F6 | U35: F7
B36: 17
B37: 18
B38: 19 | J38: Calculations
B39: 20
B40: 21
B41: 22 | K41: Element 1 | L41: Element 2 | M41: Element 3 | N41: Element 4
...

Sheet 2
C2: Element 1* | D2: Element 2* | E2: Element 3* | F2: Element 4 | H2: Key | K2: Month | L2: Element 1 Standard 1 Complaints | M2: Element 1 Standard 2 Service Recovery Missed | N2: Element 2 Standard 1 Unsigned Notes > 48 Hours | O2: Element 2 Standard 2 Exceptions | P2: Element 2 Standard 3 Non Standard Templates | Q2: Element 3 Standard 1 Encounters | R2: Element 3 Standard 2 Optician Caused Delays | S2: Element 4 Standard 1 TMS Modules Not Done | T2: TMS Modules Assigned
B3: Standard 1 | C3: =L16 -> 0 | D3: =N16 -> 100 | E3: =Q16 -> 3.1466308 | F3: =S16 -> 100 | I3: Unacceptable | K3: 10 | L3: 0 | M3: 0 | N3: 0 | O3: 1 | P3: 0 | Q3: 286 | R3: 0 | S3: 0 | T3: 0
B4: Standard 2 | C4: =M16 -> 100 | D4: =O16 -> 0.17074559 | E4: =R15 -> 0 | F4: =R34 -> 0 | I4: Minimally Successful | K4: 11 | L4: 0 | M4: 0 | N4: 0 | O4: 0 | P4: 0 | Q4: 396 | R4: 0 | S4: 0 | T4: 5
B5: Standard 3 | C5: =K34 -> 0 | D5: =P16 -> 100 | E5: =P34 -> 10 | F5: =S34 -> 0 | I5: Fully Successful | K5: 12 | L5: 0 | M5: 0 | N5: 0 | O5: 1 | P5: 0 | Q5: 299 | R5: 0 | S5: 0 | T5: 1
B6: Standard 4 | C6: =L34 -> 2 | D6: =N34 -> 10 | E6: =Q34 -> 1 | F6: =T34 -> 0 | I6: Exceptional | K6: 1 | L6: 0 | M6: 0 | N6: 0 | O6: 2 | P6: 0 | Q6: 196 | R6: 0 | S6: 0 | T6: 8
B7: Standard 5 | C7: =M34 -> 0 | D7: =O34 -> 1 | F7: =U34 -> 7 | I7: Not Fulfilled | K7: 2 | L7: 0 | M7: 0 | N7: 0 | O7: 0 | P7: 0 | Q7: 228 | R7: 0 | S7: 0 | T7: 1
B8: Standard Final | C8: =K42 -> Exceptional | D8: =L42 -> Exceptional | E8: =M42 -> Exceptional | F8: =N42 -> Exceptional | I8: Fulfilled | K8: 3 | L8: 0 | M8: 0 | N8: 0 | O8: 1 | P8: 0 | Q8: 293 | R8: 0 | S8: 0 | T8: 3
B9: Final | C9: =N44 -> OutStanding | I9: Outstanding | K9: 4 | L9: 0 | M9: 0 | N9: 0 | O9: 0 | P9: 0 | Q9: 250 | R9: 0 | S9: 0 | T9: 2
H10: * | I10: Critical Element | K10: 5 | L10: 0 | M10: 0 | N10: 0 | O10: 1 | P10: 0 | Q10: 179 | R10: 0 | S10: 0
K11: 6 | L11: 0 | M11: 0 | N11: 0 | O11: 0 | P11: 0 | Q11: 727 | R11: 0 | S11: 0
B12: Pay Period | C12: Regular | D12: OT | E12: LA | F12: LS | G12: Holiday | H12: Other | K12: 7 | L12: 0 | M12: 0 | N12: 0 | O12: 0 | P12: 0 | Q12: 660 | R12: 0 | S12: 0
B13: 20 | C13: 50 | D13: 0 | E13: 0 | F13: 0 | G13: 8 | H13: 22 | K13: 8
B14: 21 | C14: 49.5 | D14: 0.5 | E14: 0 | F14: 0.5 | G14: 0 | H14: 30 | K14: 9
B15: 22 | C15: 52 | D15: 2 | E15: 0 | F15: 0 | G15: 8 | H15: 20 | K15: Total | L15: =SUM(L3:L14) -> 0 | M15: =SUM(M3:M14) -> 0 | N15: =SUM(N3:N14) -> 0 | O15: =SUM(O3:O14) -> 6 | P15: =SUM(P3:P14) -> 0 | Q15: =SUM(Q3:Q14) -> 3514 | R15: =SUM(R3:R14) -> 0 | S15: =SUM(S3:S14) -> 0 | T15: =SUM(T3:T14) -> 20
B16: 23 | C16: 38 | D16: 0 | E16: 8 | F16: 0 | G16: 8 | H16: 24 | K16: % | L16: =SUM((L15/Q15)*100) -> 0 | M16: =SUM((1-((M15)/Q15))*100) -> 100 | N16: =SUM((1-(N15/Q15))*100) -> 100 | O16: =SUM(O15/Q15)*100 -> 0.17074559 | P16: =SUM((1-(P15/Q15))*100) -> 100 | Q16: =Q15/F47 -> 3.1466308 | S16: =SUM((1-(S15/T15))*100) -> 100
B17: 24 | C17: 63 | D17: 0 | E17: 0 | F17: 3 | G17: 0 | H17: 14 | K17: Cell | L17: C3 | M17: C4 | N17: D3 | O17: D4 | P17: D5 | Q17: E3 | R17: E4 | S17: F3
B18: 25 | C18: 44.5 | D18: 0 | E18: 0 | F18: 6.5 | G18: 20 | H18: 9
B19: 26 | C19: 60 | D19: 0 | E19: 1 | F19: 11 | G19: 8 | H19: 2 | J19: Month | K19: Element 1 Standard 3 Deescalations | L19: Element 1 Standard 4 Awards | M19: Element 1 Standard 5 Misc Vouluntary Service | N19: Element 2 Standard 4 Other staff assists | O19: Element 2 Standard 5 Process Improvement | P19: Element 3 Standard 3 Out of scope work | Q19: Element 3 Standard 4 Suggestions | R19: Element 4 Standard 2 Certifications Missing | S19: Element 4 Standard 3 New Certification | T19: Element 4 Standard 4 CE Credits | U19: Element 4 Standard 5 Voluntairy Extra Training
B20: 1 | C20: 34 | D20: 0 | E20: 0 | F20: 22 | G20: 8 | H20: 16
B21: 2 | C21: 80 | D21: 0 | E21: 0 | F21: 0 | G21: 0 | H21: 0
B22: 3 | C22: 69.5 | D22: 0 | E22: 0.5 | F22: 2 | G22: 8 | H22: 0 | J22: 10 | K22: 0 | L22: 0 | M22: 0 | N22: 1 | O22: 0 | P22: 1 | Q22: 0 | R22: 0 | S22: 0 | T22: 0 | U22: 1
B23: 4 | C23: 73 | D23: 0 | E23: 0 | F23: 7 | G23: 0 | H23: 0 | J23: 11 | K23: 0 | L23: 0 | M23: 0 | N23: 1 | O23: 0 | P23: 1 | Q23: 0 | R23: 0 | S23: 0 | T23: 0 | U23: 1
B24: 5 | C24: 80 | D24: 0 | E24: 0 | F24: 0 | G24: 0 | H24: 0 | J24: 12 | K24: 0 | L24: 2 | M24: 0 | N24: 1 | O24: 0 | P24: 1 | Q24: 0 | R24: 0 | S24: 0 | T24: 0 | U24: 1
B25: 6 | C25: 59.75 | D25: 0.25 | E25: 0.25 | F25: 8 | G25: 0 | H25: 12 | J25: 1 | K25: 0 | L25: 0 | M25: 0 | N25: 1 | O25: 1 | P25: 1 | Q25: 0 | R25: 0 | S25: 0 | T25: 0 | U25: 0
B26: 7 | C26: 55 | D26: 0 | E26: 1 | F26: 0 | G26: 0 | H26: 24 | J26: 2 | K26: 0 | L26: 0 | M26: 0 | N26: 1 | O26: 0 | P26: 1 | Q26: 0 | R26: 0 | S26: 0 | T26: 0 | U26: 0
B27: 8 | C27: 50.5 | D27: 0 | E27: 8 | F27: 1.5 | G27: 0 | H27: 20 | J27: 3 | K27: 0 | L27: 0 | M27: 0 | N27: 1 | O27: 0 | P27: 1 | Q27: 0 | R27: 0 | S27: 0 | T27: 0 | U27: 1
B28: 9 | C28: 56 | D28: 0 | E28: 8 | F28: 0 | G28: 0 | H28: 16 | J28: 4 | K28: 0 | L28: 0 | M28: 0 | N28: 1 | O28: 0 | P28: 1 | Q28: 0 | R28: 0 | S28: 0 | T28: 0 | U28: 0
B29: 10 | C29: 20 | D29: 0.5 | E29: 40 | F29: 0 | G29: 8 | H29: 12 | J29: 5 | K29: 0 | M29: 0 | N29: 1 | O29: 0 | P29: 1 | Q29: 1 | R29: 0 | S29: 0 | U29: 1
B30: 11 | C30: 56 | D30: 0 | E30: 8 | F30: 0 | G30: 0 | H30: 16 | J30: 6 | K30: 0 | M30: 0 | N30: 1 | O30: 0 | P30: 1 | Q30: 0 | R30: 0 | S30: 0 | U30: 1
B31: 12 | C31: 22 | D31: 0 | E31: 32 | F31: 2 | G31: 8 | H31: 16 | J31: 7 | K31: 0 | M31: 0 | N31: 1 | O31: 0 | P31: 1 | Q31: 0 | R31: 0 | S31: 0 | U31: 1
B32: 13 | C32: 40.5 | D32: 0 | E32: 8 | F32: 3.5 | G32: 0 | H32: 28 | J32: 8
B33: 14 | C33: 4.25 | D33: 0 | E33: 0 | F33: 1.5 | G33: 0 | H33: 36 | J33: 9
B34: 15 | C34: 56 | D34: 0 | E34: 0 | F34: 8 | G34: 0 | H34: 16 | J34: Total | K34: =SUM(K22:K33) -> 0 | L34: =SUM(L22:L33) -> 2 | M34: =SUM(M22:M33) -> 0 | N34: =SUM(N22:N33) -> 10 | O34: =SUM(O22:O33) -> 1 | P34: =SUM(P22:P33) -> 10 | Q34: =SUM(Q22:Q33) -> 1 | R34: =SUM(R22:R33) -> 0 | ... U34: =SUM(U22:U33) -> 7
B35: 16 | J35: Cell | K35: C5 | L35: C6 | M35: C7 | N35: D6 | O35: D7 | P35: E5 | Q35: E6 | R35: F4 | S35: F5 | T35: F6 | U35: F7
B36: 17
B37: 18
B38: 19 | J38: Calculations
B39: 20
B40: 21
B41: 22 | K41: Element 1 | L41: Element 2 | M41: Element 3 | N41: Element 4
...

Sheet 3
C2: Element 1* | D2: Element 2* | E2: Element 3* | F2: Element 4 | H2: Key | K2: Month | L2: Element 1 Standard 1 Complaints | M2: Element 1 Standard 2 Service Recovery Missed | N2: Element 2 Standard 1 Unsigned Notes > 48 Hours | O2: Element 2 Standard 2 Exceptions | P2: Element 2 Standard 3 Non Standard Templates | Q2: Element 3 Standard 1 Encounters | R2: Element 3 Standard 2 Optician Caused Delays | S2: Element 4 Standard 1 TMS Modules Not Done | T2: TMS Modules Assigned
B3: Standard 1 | C3: =L16 -> 0 | D3: =N16 -> 99.884393 | E3: =Q16 -> 3.1064823 | F3: =S16 -> 100 | I3: Unacceptable | K3: 10 | L3: 0 | M3: 0 | N3: 2 | O3: 0 | P3: 0 | Q3: 307 | R3: 0 | S3: 0 | T3: 5
B4: Standard 2 | C4: =M16 -> 100 | D4: =O16 -> 0.092485549 | E4: =R15 -> 0 | F4: =R34 -> 0 | I4: Minimally Successful | K4: 11 | L4: 0 | M4: 0 | N4: 1 | O4: 0 | P4: 0 | Q4: 200 | R4: 0 | S4: 0 | T4: 3
B5: Standard 3 | C5: =K34 -> 2 | D5: =P16 -> 100 | E5: =P34 -> 4 | F5: =S34 -> 0 | I5: Fully Successful | K5: 12 | L5: 0 | M5: 0 | N5: 0 | O5: 1 | P5: 0 | Q5: 525 | R5: 0 | S5: 0 | T5: 4
B6: Standard 4 | C6: =L34 -> 2 | D6: =N34 -> 2 | E6: =Q34 -> 2 | F6: =T34 -> 8 | I6: Exceptional | K6: 1 | L6: 0 | M6: 0 | N6: 0 | O6: 1 | P6: 0 | Q6: 246 | R6: 0 | S6: 0 | T6: 0
B7: Standard 5 | C7: =M34 -> 2 | D7: =O34 -> 7 | F7: =U34 -> 5 | I7: Not Fulfilled | K7: 2 | L7: 0 | M7: 0 | N7: 0 | O7: 0 | P7: 0 | Q7: 277 | R7: 0 | S7: 0 | T7: 4
B8: Standard Final | C8: =K42 -> Exceptional | D8: =L42 -> Exceptional | E8: =M42 -> Exceptional | F8: =N42 -> Exceptional | I8: Fulfilled | K8: 3 | L8: 0 | M8: 0 | N8: 0 | O8: 0 | P8: 0 | Q8: 240 | R8: 0 | S8: 0 | T8: 2
B9: Final | C9: =N44 -> OutStanding | I9: Outstanding | K9: 4 | L9: 0 | M9: 0 | N9: 0 | O9: 0 | P9: 0 | Q9: 370 | R9: 0 | S9: 0 | T9: 7
H10: * | I10: Critical Element | K10: 5 | L10: 0 | M10: 0 | N10: 0 | O10: 1 | P10: 0 | Q10: 385 | R10: 0 | S10: 0
K11: 6 | L11: 0 | M11: 0 | N11: 0 | O11: 0 | P11: 0 | Q11: 1096 | R11: 0 | S11: 0
B12: Pay Period | C12: Regular | D12: OT | E12: LA | F12: LS | G12: Holiday | H12: Other | K12: 7 | L12: 0 | M12: 0 | N12: 0 | O12: 1 | P12: 0 | Q12: 679 | R12: 0 | S12: 0
B13: 20 | C13: 53.5 | D13: 8 | E13: 4 | F13: 2.5 | G13: 10 | H13: 10 | K13: 8 | N13: 2
B14: 21 | C14: 55 | D14: 15 | E14: 0 | F14: 15 | G14: 0 | H14: 10 | K14: 9
B15: 22 | C15: 35 | D15: 8 | E15: 0 | F15: 25 | G15: 10 | H15: 10 | K15: Total | L15: =SUM(L3:L14) -> 0 | M15: =SUM(M3:M14) -> 0 | N15: =SUM(N3:N14) -> 5 | O15: =SUM(O3:O14) -> 4 | P15: =SUM(P3:P14) -> 0 | Q15: =SUM(Q3:Q14) -> 4325 | R15: =SUM(R3:R14) -> 0 | S15: =SUM(S3:S14) -> 0 | T15: =SUM(T3:T14) -> 25
B16: 23 | C16: 60 | D16: 7.5 | E16: 0 | F16: 0 | G16: 10 | H16: 10 | K16: % | L16: =SUM((L15/Q15)*100) -> 0 | M16: =SUM((1-((M15)/Q15))*100) -> 100 | N16: =SUM((1-(N15/Q15))*100) -> 99.884393 | O16: =SUM(O15/Q15)*100 -> 0.092485549 | P16: =SUM((1-(P15/Q15))*100) -> 100 | Q16: =Q15/F47 -> 3.1064823 | S16: =SUM((1-(S15/T15))*100) -> 100
B17: 24 | C17: 65 | D17: 17.5 | E17: 0 | F17: 5 | G17: 0 | H17: 10 | K17: Element/ Standard | L17: 1/1 | M17: 1/2 | N17: 2/1 | O17: 2/2 | P17: 2/3 | Q17: 3/1 | R17: 3/2 | S17: 4/1
B18: 25 | C18: 23.5 | D18: 13.5 | E18: 0 | F18: 5 | G18: 11.5 | H18: 10
B19: 26 | C19: 60 | D19: 17.25 | E19: 0 | F19: 0 | G19: 10 | H19: 10 | J19: Month | K19: Element 1 Standard 3 Deescalations | L19: Element 1 Standard 4 Awards | M19: Element 1 Standard 5 Misc Vouluntary Service | N19: Element 2 Standard 4 Other staff assists | O19: Element 2 Standard 5 Process Improvement | P19: Element 3 Standard 3 Out of scope work | Q19: Element 3 Standard 4 Suggestions | R19: Element 4 Standard 2 Certifications Missing | S19: Element 4 Standard 3 New Certification | T19: Element 4 Standard 4 CE Credits | U19: Element 4 Standard 5 Voluntairy Extra Training
B20: 1 | C20: 50 | D20: 16.5 | E20: 0 | F20: 10 | G20: 10 | H20: 10
B21: 2 | C21: 59 | D21: 12 | E21: 0 | F21: 11 | G21: 0 | H21: 10
B22: 3 | C22: 50 | D22: 17 | E22: 10 | F22: 0 | G22: 10 | H22: 10 | J22: 10 | K22: 0 | L22: 1 | M22: 0 | N22: 0 | O22: 0 | P22: 0 | Q22: 0 | R22: 0 | S22: 0 | T22: 1 | U22: 1
B23: 4 | C23: 65 | D23: 8 | E23: 0 | F23: 5 | G23: 0 | H23: 10 | J23: 11 | K23: 0 | L23: 0 | M23: 0 | N23: 0 | O23: 0 | P23: 0 | Q23: 0 | R23: 0 | S23: 0 | T23: 1 | U23: 0
B24: 5 | C24: 70 | D24: 9.5 | E24: 0 | F24: 0 | G24: 0 | H24: 10 | J24: 12 | K24: 0 | L24: 0 | M24: 1 | N24: 1 | O24: 1 | P24: 1 | Q24: 1 | R24: 0 | S24: 0 | T24: 1 | U24: 0
B25: 6 | C25: 60 | D25: 17.75 | E25: 0 | F25: 10 | G25: 0 | H25: 10 | J25: 1 | K25: 1 | L25: 0 | M25: 1 | N25: 1 | O25: 1 | P25: 1 | Q25: 1 | R25: 0 | S25: 0 | T25: 1 | U25: 0
B26: 7 | C26: 70 | D26: 9.5 | E26: 0 | F26: 0 | G26: 0 | H26: 10 | J26: 2 | K26: 0 | L26: 0 | M26: 0 | N26: 0 | O26: 1 | P26: 0 | Q26: 0 | R26: 0 | S26: 0 | T26: 1 | U26: 0
B27: 8 | C27: 65 | D27: 9 | E27: 5 | F27: 0 | G27: 0 | H27: 10 | J27: 3 | K27: 0 | L27: 0 | M27: 0 | N27: 0 | O27: 1 | P27: 0 | Q27: 0 | R27: 0 | S27: 0 | T27: 1 | U27: 1
B28: 9 | C28: 46 | D28: 9 | E28: 0 | F28: 24 | G28: 0 | H28: 10 | J28: 4 | K28: 0 | L28: 0 | M28: 0 | N28: 0 | O28: 1 | P28: 0 | Q28: 0 | R28: 0 | S28: 0 | T28: 1 | U28: 2
B29: 10 | C29: 60 | D29: 19.75 | E29: 0 | F29: 0 | G29: 10 | H29: 10 | J29: 5 | K29: 1 | L29: 0 | M29: 0 | N29: 0 | O29: 1 | P29: 1 | Q29: 0 | R29: 0 | S29: 0 | T29: 1 | U29: 1
B30: 11 | C30: 65 | D30: 16.5 | E30: 0 | F30: 5 | G30: 0 | H30: 10 | J30: 6 | K30: 0 | L30: 0 | M30: 0 | N30: 0 | O30: 1 | P30: 0 | Q30: 0 | R30: 0 | S30: 0 | T30: 0 | U30: 0
B31: 12 | C31: 60 | D31: 10 | E31: 0 | F31: 0 | G31: 10 | H31: 10 | J31: 7 | K31: 0 | L31: 0 | M31: 0 | N31: 0 | O31: 0 | P31: 1 | Q31: 0 | R31: 0 | S31: 0 | T31: 0 | U31: 0
B32: 13 | C32: 20 | D32: 0 | E32: 40 | F32: 0 | G32: 10 | H32: 10 | J32: 8 | L32: 1 | S32: 0
B33: 14 | C33: 40 | D33: 19 | E33: 30 | F33: 0 | G33: 0 | H33: 10 | J33: 9
B34: 15 | J34: Total | K34: =SUM(K22:K33) -> 2 | L34: =SUM(L22:L33) -> 2 | M34: =SUM(M22:M33) -> 2 | N34: =SUM(N22:N33) -> 2 | O34: =SUM(O22:O33) -> 7 | P34: =SUM(P22:P33) -> 4 | Q34: =SUM(Q22:Q33) -> 2 | R34: =SUM(R22:R33) -> 0 | ... U34: =SUM(U22:U33) -> 5
B35: 16 | J35: Element/ Standard | K35: 1/3 | L35: 1/4 | M35: 1/5 | N35: 2/4 | O35: 2/5 | P35: 3/3 | Q35: 3/4 | R35: 4/2 | S35: 4/3 | T35: 4/4 | U35: 4/5
B36: 17
B37: 18
B38: 19 | J38: Calculations
B39: 20
B40: 21
B41: 22 | K41: Element 1 | L41: Element 2 | M41: Element 3 | N41: Element 4
...

Sheet 4
C2: Element 1* | D2: Element 2* | E2: Element 3* | F2: Element 4 | H2: Key | K2: Month | L2: Element 1 Standard 1 Complaints | M2: Element 1 Standard 2 Service Recovery Missed | N2: Element 2 Standard 1 Unsigned Notes > 48 Hours | O2: Element 2 Standard 2 Exceptions | P2: Element 2 Standard 3 Non Standard Templates | Q2: Element 3 Standard 1 Encounters | R2: Element 3 Standard 2 Optician Caused Delays | S2: Element 4 Standard 1 TMS Modules Not Done | T2: TMS Modules Assigned
B3: Standard 1 | C3: =L16 -> 0 | D3: =N16 -> 100 | E3: =Q16 -> 3.109959 | F3: =S16 -> 100 | I3: Unacceptable | K3: 10 | L3: 0 | M3: 0 | N3: 0 | O3: 2 | P3: 0 | Q3: 387 | R3: 0 | S3: 0 | T3: 10
B4: Standard 2 | C4: =M16 -> 100 | D4: =O16 -> 0.30870549 | E4: =R15 -> 0 | F4: =R34 -> 0 | I4: Minimally Successful | K4: 11 | L4: 0 | M4: 0 | N4: 0 | O4: 0 | P4: 0 | Q4: 455 | R4: 0 | S4: 0 | T4: 1
B5: Standard 3 | C5: =K34 -> 1 | D5: =P16 -> 100 | E5: =P34 -> 3 | F5: =S34 -> 0 | I5: Fully Successful | K5: 12 | L5: 0 | M5: 0 | N5: 0 | O5: 1 | P5: 0 | Q5: 449 | R5: 0 | S5: 0 | T5: 3
B6: Standard 4 | C6: =L34 -> 15 | D6: =N34 -> 1 | E6: =Q34 -> 4 | F6: =T34 -> 0 | I6: Exceptional | K6: 1 | L6: 0 | M6: 0 | N6: 0 | O6: 1 | P6: 0 | Q6: 315 | R6: 0 | S6: 0 | T6: 3
B7: Standard 5 | C7: =M34 -> 1 | D7: =O34 -> 3 | F7: =U34 -> 1 | I7: Not Fulfilled | K7: 2 | L7: 0 | M7: 0 | N7: 0 | O7: 2 | P7: 0 | Q7: 328 | R7: 0 | S7: 0 | T7: 1
B8: Standard Final | C8: =K42 -> Exceptional | D8: =L42 -> Exceptional | E8: =M42 -> Exceptional | F8: =N42 -> Exceptional | I8: Fulfilled | K8: 3 | L8: 0 | M8: 0 | N8: 0 | O8: 0 | P8: 0 | Q8: 420 | R8: 0 | S8: 0 | T8: 2
B9: Final | C9: =N44 -> OutStanding | I9: Outstanding | K9: 4 | L9: 0 | M9: 0 | N9: 0 | O9: 0 | P9: 0 | Q9: 381 | R9: 0 | S9: 0 | T9: 1
H10: * | I10: Critical Element | K10: 5 | L10: 0 | M10: 0 | N10: 0 | O10: 3 | P10: 0 | Q10: 302 | R10: 0
K11: 6 | L11: 0 | M11: 0 | N11: 0 | O11: 0 | P11: 0 | Q11: 975 | R11: 0
B12: Pay Period | C12: Regular | D12: OT | E12: LA | F12: LS | G12: Holiday | H12: Other | K12: 7 | L12: 0 | M12: 0 | N12: 0 | O12: 6 | P12: 0 | Q12: 847 | R12: 0
B13: 20 | C13: 71.5 | D13: 0.5 | E13: 0.5 | F13: 0 | G13: 8 | H13: 0 | K13: 8
B14: 21 | C14: 79.5 | D14: 0.5 | E14: 0 | F14: 0.5 | G14: 0 | H14: 0 | K14: 9
B15: 22 | C15: 64 | D15: 1 | E15: 8 | F15: 0 | G15: 8 | H15: 0 | K15: Total | L15: =SUM(L3:L14) -> 0 | M15: =SUM(M3:M14) -> 0 | N15: =SUM(N3:N14) -> 0 | O15: =SUM(O3:O14) -> 15 | P15: =SUM(P3:P14) -> 0 | Q15: =SUM(Q3:Q14) -> 4859 | R15: =SUM(R3:R14) -> 0 | S15: =SUM(S3:S14) -> 0 | T15: =SUM(T3:T14) -> 21
B16: 23 | C16: 64 | D16: 1.25 | E16: 8 | F16: 0 | G16: 8 | H16: 0 | K16: % | L16: =SUM((L15/Q15)*100) -> 0 | M16: =SUM((1-((M15)/Q15))*100) -> 100 | N16: =SUM((1-(N15/Q15))*100) -> 100 | O16: =SUM(O15/Q15)*100 -> 0.30870549 | P16: =SUM((1-(P15/Q15))*100) -> 100 | Q16: =Q15/F47 -> 3.109959 | S16: =SUM((1-(S15/T15))*100) -> 100
B17: 24 | C17: 79.25 | D17: 1.75 | E17: 0 | F17: 0.75 | G17: 0 | H17: 0 | K17: Cell | L17: C3 | M17: C4 | N17: D3 | O17: D4 | P17: D5 | Q17: E3 | R17: E4 | S17: F3
B18: 25 | C18: 56 | D18: 0.5 | E18: 0 | F18: 0 | G18: 24 | H18: 0
B19: 26 | C19: 54.25 | D19: 0 | E19: 0 | F19: 17.75 | G19: 8 | H19: 0 | J19: Month | K19: Element 1 Standard 3 Deescalations | L19: Element 1 Standard 4 Awards | M19: Element 1 Standard 5 Misc Vouluntary Service | N19: Element 2 Standard 4 Other staff assists | O19: Element 2 Standard 5 Process Improvement | P19: Element 3 Standard 3 Out of scope work | Q19: Element 3 Standard 4 Suggestions | R19: Element 4 Standard 2 Certifications Missing | S19: Element 4 Standard 3 New Certification | T19: Element 4 Standard 4 CE Credits | U19: Element 4 Standard 5 Voluntairy Extra Training
B20: 1 | C20: 71 | D20: 1.5 | E20: 0 | F20: 1 | G20: 8 | H20: 0
B21: 2 | C21: 72 | D21: 1.25 | E21: 0 | F21: 8 | G21: 0 | H21: 0
B22: 3 | C22: 71.45 | D22: 0.5 | E22: 0.25 | F22: 0 | G22: 8 | H22: 0 | J22: 10 | K22: 0 | L22: 0 | M22: 0 | N22: 0 | O22: 0 | P22: 0 | Q22: 1 | R22: 0 | S22: 0 | T22: 0 | U22: 0
B23: 4 | C23: 78.5 | D23: 1 | E23: 0 | F23: 1.5 | G23: 0 | H23: 0 | J23: 11 | K23: 0 | L23: 0 | M23: 0 | N23: 0 | O23: 0 | P23: 0 | Q23: 0 | R23: 0 | S23: 0 | T23: 0 | U23: 1
B24: 5 | C24: 68.5 | D24: 0 | E24: 8 | F24: 3.5 | G24: 0 | H24: 0 | J24: 12 | K24: 0 | L24: 0 | M24: 0 | N24: 0 | O24: 0 | P24: 0 | Q24: 0 | R24: 0 | S24: 0 | T24: 0 | U24: 0
B25: 6 | C25: 79.5 | D25: 0 | E25: 0 | F25: 0.5 | G25: 0 | H25: 0 | J25: 1 | K25: 1 | L25: 0 | M25: 0 | N25: 0 | O25: 1 | P25: 1 | Q25: 1 | R25: 0 | S25: 0 | T25: 0 | U25: 0
B26: 7 | C26: 72 | D26: 0.5 | E26: 8 | F26: 0 | G26: 0 | H26: 0 | J26: 2 | K26: 0 | L26: 0 | M26: 0 | N26: 0 | O26: 0 | P26: 0 | Q26: 0 | R26: 0 | S26: 0 | T26: 0 | U26: 0
B27: 8 | C27: 68.25 | D27: 0 | E27: 0 | F27: 11.75 | G27: 0 | H27: 0 | J27: 3 | K27: 0 | L27: 3 | M27: 0 | N27: 0 | O27: 0 | P27: 0 | Q27: 1 | R27: 0 | S27: 0 | T27: 0 | U27: 0
B28: 9 | C28: 78.5 | D28: 0 | E28: 1.5 | F28: 0 | G28: 0 | H28: 0 | J28: 4 | K28: 0 | L28: 2 | M28: 0 | N28: 1 | O28: 0 | P28: 1 | Q28: 1 | R28: 0 | S28: 0 | T28: 0 | U28: 0
B29: 10 | C29: 48 | D29: 0 | E29: 24 | F29: 0 | G29: 8 | H29: 0 | J29: 5 | K29: 0 | L29: 3 | M29: 0 | N29: 0 | O29: 1 | P29: 0 | Q29: 0 | R29: 0 | S29: 0 | T29: 0 | U29: 0
B30: 11 | C30: 80 | D30: 0.5 | E30: 0 | F30: 0 | G30: 0 | H30: 0 | J30: 6 | K30: 0 | L30: 5 | M30: 0 | N30: 0 | O30: 1 | P30: 0 | Q30: 0 | R30: 0 | S30: 0 | T30: 0 | U30: 0
B31: 12 | C31: 64 | D31: 0.5 | E31: 0 | F31: 8 | G31: 8 | H31: 0 | J31: 7 | K31: 0 | L31: 2 | M31: 1 | N31: 0 | O31: 0 | P31: 1 | Q31: 0 | R31: 0 | S31: 0 | T31: 0 | U31: 0
B32: 13 | C32: 71.5 | D32: 0 | E32: 8 | F32: 0.5 | G32: 0 | H32: 0 | J32: 8
B33: 14 | C33: 79 | D33: 0.45 | E33: 0 | F33: 1 | G33: 0 | H33: 0 | J33: 9
B34: 15 | C34: 80 | D34: 0 | E34: 0 | F34: 0 | G34: 0 | H34: 0 | J34: Total | K34: =SUM(K22:K33) -> 1 | L34: =SUM(L22:L33) -> 15 | M34: =SUM(M22:M33) -> 1 | N34: =SUM(N22:N33) -> 1 | O34: =SUM(O22:O33) -> 3 | P34: =SUM(P22:P33) -> 3 | Q34: =SUM(Q22:Q33) -> 4 | R34: =SUM(R22:R33) -> 0 | ... U34: =SUM(U22:U33) -> 1
B35: 16 | J35: Cell | K35: C5 | L35: C6 | M35: C7 | N35: D6 | O35: D7 | P35: E5 | Q35: E6 | R35: F4 | S35: F5 | T35: F6 | U35: F7
B36: 17
B37: 18
B38: 19 | J38: Calculations
B39: 20
B40: 21
B41: 22 | K41: Element 1 | L41: Element 2 | M41: Element 3 | N41: Element 4
...

Sheet 5
C2: Element 1* | D2: Element 2* | E2: Element 3* | F2: Element 4 | H2: Key | K2: Month | L2: Element 1 Standard 1 Complaints | M2: Element 1 Standard 2 Service Recovery Missed | N2: Element 2 Standard 1 Unsigned Notes > 48 Hours | O2: Element 2 Standard 2 Exceptions | P2: Element 2 Standard 3 Non Standard Templates | Q2: Element 3 Standard 1 Encounters | R2: Element 3 Standard 2 Optician Caused Delays | S2: Element 4 Standard 1 TMS Modules Not Done | T2: TMS Modules Assigned
B3: Standard 1 | C3: =L16 -> 0 | D3: =N16 -> 100 | E3: =Q16 -> 3.9651979 | F3: =S16 -> 100 | I3: Unacceptable | K3: 10 | L3: 0 | M3: 0 | N3: 0 | O3: 0 | P3: 0 | Q3: 506 | R3: 0 | S3: 0 | T3: 1
B4: Standard 2 | C4: =M16 -> 100 | D4: =O16 -> 0.052872753 | E4: =R15 -> 0 | F4: =R34 -> 0 | I4: Minimally Successful | K4: 11 | L4: 0 | M4: 0 | N4: 0 | O4: 0 | P4: 0 | Q4: 592 | R4: 0 | S4: 0 | T4: 2
B5: Standard 3 | C5: =K34 -> 0 | D5: =P16 -> 100 | E5: =P34 -> 7 | F5: =S34 -> 0 | I5: Fully Successful | K5: 12 | L5: 0 | M5: 0 | N5: 0 | O5: 0 | P5: 0 | Q5: 307 | R5: 0 | S5: 0 | T5: 6
B6: Standard 4 | C6: =L34 -> 5 | D6: =N34 -> 0 | E6: =Q34 -> 1 | F6: =T34 -> 1 | I6: Exceptional | K6: 1 | L6: 0 | M6: 0 | N6: 0 | O6: 1 | P6: 0 | Q6: 469 | R6: 0 | S6: 0 | T6: 3
B7: Standard 5 | C7: =M34 -> 0 | D7: =O34 -> 1 | F7: =U34 -> 0 | I7: Not Fulfilled | K7: 2 | L7: 0 | M7: 0 | N7: 0 | O7: 0 | P7: 0 | Q7: 417 | R7: 0 | S7: 0 | T7: 0
B8: Standard Final | C8: =K42 -> Exceptional | D8: =L42 -> Exceptional | E8: =M42 -> Exceptional | F8: =N42 -> Exceptional | I8: Fulfilled | K8: 3 | L8: 0 | M8: 0 | N8: 0 | O8: 1 | P8: 0 | Q8: 539 | R8: 0 | S8: 0 | T8: 3
B9: Final | C9: =N44 -> OutStanding | I9: Outstanding | K9: 4 | L9: 0 | M9: 0 | N9: 0 | O9: 0 | P9: 0 | Q9: 441 | R9: 0 | S9: 0 | T9: 1
H10: * | I10: Critical Element | K10: 5 | L10: 0 | M10: 0 | N10: 0 | O10: 0 | P10: 0 | Q10: 279 | R10: 0 | S10: 0
K11: 6 | L11: 0 | M11: 0 | N11: 0 | O11: 1 | P11: 0 | Q11: 1258 | R11: 0 | S11: 0
B12: Pay Period | C12: Regular | D12: OT | E12: LA | F12: LS | G12: Holiday | H12: Other | K12: 7 | L12: 0 | M12: 0 | N12: 0 | O12: 0 | P12: 0 | Q12: 866 | R12: 0 | S12: 0
B13: 20 | C13: 64 | D13: 1.25 | E13: 8 | F13: 0 | G13: 8 | H13: 0 | K13: 8
B14: 21 | C14: 69.5 | D14: 0.5 | E14: 0 | F14: 10.5 | G14: 0 | H14: 0 | K14: 9
B15: 22 | C15: 68.5 | D15: 1.75 | E15: 0 | F15: 3.5 | G15: 8 | H15: 0 | K15: Total | L15: =SUM(L3:L14) -> 0 | M15: =SUM(M3:M14) -> 0 | N15: =SUM(N3:N14) -> 0 | O15: =SUM(O3:O14) -> 3 | P15: =SUM(P3:P14) -> 0 | Q15: =SUM(Q3:Q14) -> 5674 | R15: =SUM(R3:R14) -> 0 | S15: =SUM(S3:S14) -> 0 | T15: =SUM(T3:T14) -> 16
B16: 23 | C16: 64 | D16: 1 | E16: 8 | F16: 0 | G16: 8 | H16: 0 | K16: % | L16: =SUM((L15/Q15)*100) -> 0 | M16: =SUM((1-((M15)/Q15))*100) -> 100 | N16: =SUM((1-(N15/Q15))*100) -> 100 | O16: =SUM(O15/Q15)*100 -> 0.052872753 | P16: =SUM((1-(P15/Q15))*100) -> 100 | Q16: =Q15/F47 -> 3.9651979 | S16: =SUM((1-(S15/T15))*100) -> 100
B17: 24 | C17: 37.5 | D17: 1.25 | E17: 40 | F17: 2.5 | G17: 0 | H17: 0 | K17: Cell | L17: C3 | M17: C4 | N17: D3 | O17: D4 | P17: D5 | Q17: E3 | R17: E4 | S17: F3
B18: 25 | C18: 56 | D18: 1.5 | E18: 16 | F18: 0 | G18: 8 | H18: 0
B19: 26 | C19: 44 | D19: 1 | E19: 24 | F19: 4 | G19: 8 | H19: 0 | J19: Month | K19: Element 1 Standard 3 Deescalations | L19: Element 1 Standard 4 Awards | M19: Element 1 Standard 5 Misc Vouluntary Service | N19: Element 2 Standard 4 Other staff assists | O19: Element 2 Standard 5 Process Improvement | P19: Element 3 Standard 3 Out of scope work | Q19: Element 3 Standard 4 Suggestions | R19: Element 4 Standard 2 Certifications Missing | S19: Element 4 Standard 3 New Certification | T19: Element 4 Standard 4 CE Credits | U19: Element 4 Standard 5 Voluntairy Extra Training
B20: 1 | C20: 70 | D20: 2 | E20: 8 | F20: 2 | G20: 0 | H20: 0
B21: 2 | C21: 76.45 | D21: 1.5 | E21: 0 | F21: 3.25 | G21: 0 | H21: 0
B22: 3 | C22: 56 | D22: 1 | E22: 16 | F22: 8 | G22: 0 | H22: 0 | J22: 10 | K22: 0 | L22: 0 | M22: 0 | N22: 0 | O22: 0 | P22: 1 | Q22: 0 | R22: 0 | S22: 0 | T22: 0 | U22: 0
B23: 4 | C23: 80 | D23: 3 | E23: 0 | F23: 0 | G23: 0 | H23: 0 | J23: 11 | K23: 0 | L23: 0 | M23: 0 | N23: 0 | O23: 0 | P23: 1 | Q23: 0 | R23: 0 | S23: 0 | T23: 1 | U23: 0
B24: 5 | C24: 77 | D24: 2 | E24: 1 | F24: 2 | G24: 0 | H24: 0 | J24: 12 | K24: 0 | L24: 0 | M24: 0 | N24: 0 | O24: 0 | P24: 1 | Q24: 0 | R24: 0 | S24: 0 | T24: 0 | U24: 0
B25: 6 | C25: 75.5 | D25: 0.5 | E25: 0 | F25: 4.5 | G25: 0 | H25: 0 | J25: 1 | K25: 0 | L25: 1 | M25: 0 | N25: 0 | O25: 1 | P25: 0 | Q25: 0 | R25: 0 | S25: 0 | T25: 0 | U25: 0
B26: 7 | C26: 77.75 | D26: 0.5 | E26: 0 | F26: 2.25 | G26: 0 | H26: 0 | J26: 2 | K26: 0 | L26: 1 | M26: 0 | N26: 0 | O26: 0 | P26: 0 | Q26: 0 | R26: 0 | S26: 0 | T26: 0 | U26: 0
B27: 8 | C27: 75.5 | D27: 0 | E27: 0 | F27: 4.5 | G27: 0 | H27: 0 | J27: 3 | K27: 0 | L27: 1 | M27: 0 | N27: 0 | O27: 0 | P27: 1 | Q27: 0 | R27: 0 | S27: 0 | T27: 0 | U27: 0
B28: 9 | C28: 54 | D28: 0.25 | E28: 24 | F28: 2 | G28: 0 | H28: 0 | J28: 4 | K28: 0 | L28: 1 | M28: 0 | N28: 0 | O28: 0 | P28: 0 | Q28: 0 | R28: 0 | S28: 0 | T28: 0 | U28: 0
B29: 10 | C29: 40 | D29: 0.5 | E29: 16 | F29: 16 | G29: 8 | H29: 0 | J29: 5 | K29: 0 | L29: 0 | M29: 0 | N29: 0 | O29: 0 | P29: 1 | Q29: 0 | R29: 0 | S29: 0 | T29: 0 | U29: 0
B30: 11 | C30: 76 | D30: 0.75 | E30: 4 | F30: 0 | G30: 0 | H30: 0 | J30: 6 | K30: 0 | L30: 1 | M30: 0 | N30: 0 | O30: 0 | P30: 1 | Q30: 0 | R30: 0 | S30: 0 | T30: 0 | U30: 0
B31: 12 | C31: 64 | D31: 0 | E31: 8 | F31: 0 | G31: 8 | H31: 0 | J31: 7 | K31: 0 | L31: 0 | M31: 0 | N31: 0 | O31: 0 | P31: 1 | Q31: 1 | R31: 0 | S31: 0 | T31: 0 | U31: 0
B32: 13 | C32: 72 | D32: 0.5 | E32: 0 | F32: 0 | G32: 8 | H32: 0 | J32: 8
B33: 14 | C33: 38 | D33: 2.5 | E33: 40 | F33: 2 | G33: 0 | H33: 0 | J33: 9
B34: 15 | C34: 71.5 | D34: 0.5 | E34: 0 | F34: 8.5 | G34: 0 | H34: 0 | J34: Total | K34: =SUM(K22:K33) -> 0 | L34: =SUM(L22:L33) -> 5 | M34: =SUM(M22:M33) -> 0 | N34: =SUM(N22:N33) -> 0 | O34: =SUM(O22:O33) -> 1 | P34: =SUM(P22:P33) -> 7 | Q34: =SUM(Q22:Q33) -> 1 | R34: =SUM(R22:R33) -> 0 | ... U34: =SUM(U22:U33) -> 0
B35: 16 | J35: Cell | K35: C5 | L35: C6 | M35: C7 | N35: D6 | O35: D7 | P35: E5 | Q35: E6 | R35: F4 | S35: F5 | T35: F6 | U35: F7
B36: 17
B37: 18
B38: 19 | J38: Calculations
B39: 20
B40: 21
B41: 22 | K41: Element 1 | L41: Element 2 | M41: Element 3 | N41: Element 4
...

Sheet 6
C2: Element 1* | D2: Element 2* | E2: Element 3* | F2: Element 4 | H2: Key | K2: Month | L2: Element 1 Standard 1 Complaints | M2: Element 1 Standard 2 Service Recovery Missed | N2: Element 2 Standard 1 Unsigned Notes > 48 Hours | O2: Element 2 Standard 2 Exceptions | P2: Element 2 Standard 3 Non Standard Templates | Q2: Element 3 Standard 1 Encounters | R2: Element 3 Standard 2 Optician Caused Delays | S2: Element 4 Standard 1 TMS Modules Not Done | T2: TMS Modules Assigned
B3: Standard 1 | C3: =L16 -> 0 | D3: =N16 -> 99.981725 | E3: =Q16 -> 3.8218963 | F3: =S16 -> 100 | I3: Unacceptable | K3: 10 | L3: 0 | M3: 0 | N3: 0 | O3: 1 | P3: 0 | Q3: 519 | R3: 0 | S3: 0 | T3: 3
B4: Standard 2 | C4: =M16 -> 100 | D4: =O16 -> 0.38377193 | E4: =R15 -> 0 | F4: =R34 -> 0 | I4: Minimally Successful | K4: 11 | L4: 0 | M4: 0 | N4: 0 | O4: 0 | P4: 0 | Q4: 555 | R4: 0 | S4: 0 | T4: 1
B5: Standard 3 | C5: =K34 -> 1 | D5: =P16 -> 100 | E5: =P34 -> 1 | F5: =S34 -> 0 | I5: Fully Successful | K5: 12 | L5: 0 | M5: 0 | N5: 0 | O5: 5 | P5: 0 | Q5: 608 | R5: 0 | S5: 0 | T5: 3
B6: Standard 4 | C6: =L34 -> 4 | D6: =N34 -> 1 | E6: =Q34 -> 0 | F6: =T34 -> 0 | I6: Exceptional | K6: 1 | L6: 0 | M6: 0 | N6: 0 | O6: 3 | P6: 0 | Q6: 344 | R6: 0 | S6: 0 | T6: 5
B7: Standard 5 | C7: =M34 -> 0 | D7: =O34 -> 0 | F7: =U34 -> 0 | I7: Not Fulfilled | K7: 2 | L7: 0 | M7: 0 | N7: 0 | O7: 2 | P7: 0 | Q7: 400 | R7: 0 | S7: 0 | T7: 0
B8: Standard Final | C8: =K42 -> Exceptional | D8: =L42 -> Fully Successful | E8: =M42 -> Exceptional | F8: =N42 -> Fully Successful | I8: Fulfilled | K8: 3 | L8: 0 | M8: 0 | N8: 0 | O8: 3 | P8: 0 | Q8: 465 | R8: 0 | S8: 0 | T8: 4
B9: Final | C9: =N44 -> Fully Successful | I9: Outstanding | K9: 4 | L9: 0 | M9: 0 | N9: 0 | O9: 0 | P9: 0 | Q9: 376 | R9: 0 | S9: 0 | T9: 0
H10: * | I10: Critical Element | K10: 5 | L10: 0 | M10: 0 | N10: 1 | O10: 2 | P10: 0 | Q10: 379 | R10: 0 | S10: 0 | T10: 0
K11: 6 | L11: 0 | M11: 0 | N11: 0 | O11: 0 | P11: 0 | Q11: 768 | R11: 0 | S11: 0 | T11: 0
B12: Pay Period | C12: Regular | D12: OT | E12: LA | F12: LS | G12: Holiday | H12: Other | K12: 7 | L12: 0 | M12: 0 | N12: 0 | O12: 5 | P12: 0 | Q12: 1058 | R12: 0 | S12: 0 | T12: 1
B13: 20 | C13: 61 | D13: 0.5 | E13: 8 | F13: 3 | G13: 8 | H13: 0 | K13: 8 | S13: 0 | T13: 5
B14: 21 | C14: 72 | D14: 0.5 | E14: 8 | F14: 0 | G14: 0 | H14: 0 | K14: 9 | T14: 1
B15: 22 | C15: 68.5 | D15: 1.25 | E15: 0 | F15: 3.5 | G15: 8 | H15: 0 | K15: Total | L15: =SUM(L3:L14) -> 0 | M15: =SUM(M3:M14) -> 0 | N15: =SUM(N3:N14) -> 1 | O15: =SUM(O3:O14) -> 21 | P15: =SUM(P3:P14) -> 0 | Q15: =SUM(Q3:Q14) -> 5472 | R15: =SUM(R3:R14) -> 0 | S15: =SUM(S3:S14) -> 0 | T15: =SUM(T3:T14) -> 23
B16: 23 | C16: 63 | D16: 0.5 | E16: 0 | F16: 9 | G16: 8 | H16: 0 | K16: % | L16: =SUM((L15/Q15)*100) -> 0 | M16: =SUM((1-((M15)/Q15))*100) -> 100 | N16: =SUM((1-(N15/Q15))*100) -> 99.981725 | O16: =SUM(O15/Q15)*100 -> 0.38377193 | P16: =SUM((1-(P15/Q15))*100) -> 100 | Q16: =Q15/F47 -> 3.8218963 | S16: =SUM((1-(S15/T15))*100) -> 100
B17: 24 | C17: 69 | D17: 0 | E17: 7 | F17: 4 | G17: 0 | H17: 0 | K17: Cell | L17: C3 | M17: C4 | N17: D3 | O17: D4 | P17: D5 | Q17: E3 | R17: E4 | S17: F3
B18: 25 | C18: 56 | D18: 0 | E18: 0 | F18: 0 | G18: 21 | H18: 3
B19: 26 | C19: 56 | D19: 0 | E19: 16 | F19: 0 | G19: 8 | H19: 0 | J19: Month | K19: Element 1 Standard 3 Deescalations | L19: Element 1 Standard 4 Awards | M19: Element 1 Standard 5 Misc Vouluntary Service | N19: Element 2 Standard 4 Other staff assists | O19: Element 2 Standard 5 Process Improvement | P19: Element 3 Standard 3 Out of scope work | Q19: Element 3 Standard 4 Suggestions | R19: Element 4 Standard 2 Certifications Missing | S19: Element 4 Standard 3 New Certification | T19: Element 4 Standard 4 CE Credits | U19: Element 4 Standard 5 Voluntairy Extra Training
B20: 1 | C20: 65.25 | D20: 0 | E20: 0 | F20: 6.75 | G20: 8 | H20: 0
B21: 2 | C21: 68.5 | D21: 0 | E21: 2.5 | F21: 9 | G21: 0 | H21: 0
B22: 3 | C22: 71.5 | D22: 0 | E22: 0.5 | F22: 8 | G22: 0 | H22: 0 | J22: 10 | K22: 0 | L22: 0 | M22: 0 | N22: 0 | O22: 0 | P22: 1 | Q22: 0 | R22: 0 | S22: 0 | T22: 0 | U22: 0
B23: 4 | C23: 78 | D23: 0 | E23: 0 | F23: 2 | G23: 0 | H23: 0 | J23: 11 | K23: 1 | L23: 0 | M23: 0 | N23: 0 | O23: 0 | P23: 0 | Q23: 0 | R23: 0 | S23: 0 | T23: 0 | U23: 0
B24: 5 | C24: 72.5 | D24: 0 | E24: 0 | F24: 7.5 | G24: 0 | H24: 0 | J24: 12 | K24: 0 | L24: 0 | M24: 0 | N24: 1 | O24: 0 | P24: 0 | Q24: 0 | R24: 0 | S24: 0 | T24: 0 | U24: 0
B25: 6 | C25: 77.5 | D25: 0 | E25: 0 | F25: 2.5 | G25: 0 | H25: 0 | J25: 1 | K25: 0 | L25: 0 | M25: 0 | N25: 0 | O25: 0 | P25: 0 | Q25: 0 | R25: 0 | S25: 0 | T25: 0 | U25: 0
B26: 7 | C26: 71.5 | D26: 0 | E26: 3 | F26: 5.5 | G26: 0 | H26: 0 | J26: 2 | K26: 0 | L26: 1 | M26: 0 | N26: 0 | O26: 0 | P26: 0 | Q26: 0 | R26: 0 | S26: 0 | T26: 0 | U26: 0
B27: 8 | C27: 64 | D27: 0 | E27: 16 | F27: 0 | G27: 0 | H27: 0 | J27: 3 | K27: 0 | L27: 0 | M27: 0 | N27: 0 | O27: 0 | P27: 0 | Q27: 0 | R27: 0 | S27: 0 | T27: 0 | U27: 0
B28: 9 | C28: 62.5 | D28: 0 | E28: 17.5 | F28: 0 | G28: 0 | H28: 0 | J28: 4 | K28: 0 | L28: 0 | M28: 0 | N28: 0 | O28: 0 | P28: 0 | Q28: 0 | R28: 0 | S28: 0 | T28: 0 | U28: 0
B29: 10 | C29: 64 | D29: 0 | E29: 0 | F29: 8 | G29: 8 | H29: 0 | J29: 5 | K29: 0 | L29: 1 | M29: 0 | N29: 0 | O29: 0 | P29: 0 | Q29: 0 | R29: 0 | S29: 0 | T29: 0 | U29: 0
B30: 11 | C30: 40 | D30: 0 | E30: 40 | F30: 0 | G30: 0 | H30: 0 | J30: 6 | K30: 0 | L30: 1 | M30: 0 | N30: 0 | O30: 0 | P30: 0 | Q30: 0 | R30: 0 | S30: 0 | T30: 0 | U30: 0
B31: 12 | C31: 51.5 | D31: 0 | E31: 11.5 | F31: 9 | G31: 8 | H31: 0 | J31: 7 | K31: 0 | L31: 1 | M31: 0 | N31: 0 | O31: 0 | P31: 0 | Q31: 0 | R31: 0 | S31: 0 | T31: 0 | U31: 0
B32: 13 | C32: 64 | D32: 4 | E32: 0 | F32: 8 | G32: 8 | H32: 0 | J32: 8
B33: 14 | C33: 80 | D33: 2.25 | E33: 0 | F33: 0 | G33: 0 | H33: 0 | J33: 9
B34: 15 | C34: 46.5 | D34: 0 | E34: 33.5 | F34: 0 | G34: 0 | H34: 0 | J34: Total | K34: =SUM(K22:K33) -> 1 | L34: =SUM(L22:L33) -> 4 | M34: =SUM(M22:M33) -> 0 | N34: =SUM(N22:N33) -> 1 | O34: =SUM(O22:O33) -> 0 | P34: =SUM(P22:P33) -> 1 | Q34: =SUM(Q22:Q33) -> 0 | R34: =SUM(R22:R33) -> 0 | ... U34: =SUM(U22:U33) -> 0
B35: 16 | J35: Cell | K35: C5 | L35: C6 | M35: C7 | N35: D6 | O35: D7 | P35: E5 | Q35: E6 | R35: F4 | S35: F5 | T35: F6 | U35: F7
B36: 17
B37: 18
B38: 19 | J38: Calculations
B39: 20
B40: 21
B41: 22 | K41: Element 1 | L41: Element 2 | M41: Element 3 | N41: Element 4
...

Sheet Template
C2: Element 1* | D2: Element 2* | E2: Element 3* | F2: Element 4 | H2: Key | K2: Month | L2: Element 1 Standard 1 Complaints | M2: Element 1 Standard 2 Service Recovery Missed | N2: Element 2 Standard 1 Unsigned Notes > 48 Hours | O2: Element 2 Standard 2 Exceptions | P2: Element 2 Standard 3 Non Standard Templates | Q2: Element 3 Standard 1 Encounters | R2: Element 3 Standard 2 Optician Caused Delays | S2: Element 4 Standard 1 TMS Modules Not Done | T2: TMS Modules Assigned
B3: Standard 1 | C3: =L16 -> #DIV/0! | D3: =N16 -> #DIV/0! | E3: =Q16 -> #DIV/0! | F3: =S16 -> #DIV/0! | I3: Unacceptable | K3: 10
B4: Standard 2 | C4: =M16 -> #DIV/0! | D4: =O16 -> #DIV/0! | E4: =R15 -> 0 | F4: =R34 -> 0 | I4: Minimally Successful | K4: 11
B5: Standard 3 | C5: =K34 -> 0 | D5: =P16 -> #DIV/0! | E5: =P34 -> 0 | F5: =S34 -> 0 | I5: Fully Successful | K5: 12
B6: Standard 4 | C6: =L34 -> 0 | D6: =N34 -> 0 | E6: =Q34 -> 0 | F6: =T34 -> 0 | I6: Exceptional | K6: 1
B7: Standard 5 | C7: =M34 -> 0 | D7: =O34 -> 0 | F7: =U34 -> 0 | I7: Not Fulfilled | K7: 2
B8: Standard Final | C8: =K42 -> #DIV/0! | D8: =L42 -> #DIV/0! | E8: =M42 -> #DIV/0! | F8: =N42 -> #DIV/0! | I8: Fulfilled | K8: 3
B9: Final | C9: =N44 -> #DIV/0! | I9: Outstanding | K9: 4
H10: * | I10: Critical Element | K10: 5
K11: 6
B12: Pay Period | C12: Regular | D12: OT | E12: LA | F12: LS | G12: Holiday | H12: Other | K12: 7
B13: 20 | K13: 8
B14: 21 | K14: 9
B15: 22 | K15: Total | L15: =SUM(L3:L14) -> 0 | M15: =SUM(M3:M14) -> 0 | N15: =SUM(N3:N14) -> 0 | O15: =SUM(O3:O14) -> 0 | P15: =SUM(P3:P14) -> 0 | Q15: =SUM(Q3:Q14) -> 0 | R15: =SUM(R3:R14) -> 0 | S15: =SUM(S3:S14) -> 0 | T15: =SUM(T3:T14) -> 0
B16: 23 | K16: % | L16: =SUM((L15/Q15)*100) -> #DIV/0! | M16: =SUM((1-((M15)/Q15))*100) -> #DIV/0! | N16: =SUM((1-(N15/Q15))*100) -> #DIV/0! | O16: =SUM(O15/Q15)*100 -> #DIV/0! | P16: =SUM((1-(P15/Q15))*100) -> #DIV/0! | Q16: =Q15/F47 -> #DIV/0! | S16: =SUM((1-(S15/T15))*100) -> #DIV/0!
B17: 24 | K17: Element/ Standard | L17: 1/1 | M17: 1/2 | N17: 2/1 | O17: 2/2 | P17: 2/3 | Q17: 3/1 | R17: 3/2 | S17: 4/1
B18: 25
B19: 26 | J19: Month | K19: Element 1 Standard 3 Deescalations | L19: Element 1 Standard 4 Awards | M19: Element 1 Standard 5 Misc Vouluntary Service | N19: Element 2 Standard 4 Other staff assists | O19: Element 2 Standard 5 Process Improvement | P19: Element 3 Standard 3 Out of scope work | Q19: Element 3 Standard 4 Suggestions | R19: Element 4 Standard 2 Certifications Missing | S19: Element 4 Standard 3 New Certification | T19: Element 4 Standard 4 CE Credits | U19: Element 4 Standard 5 Voluntairy Extra Training
B20: 1
B21: 2
B22: 3 | J22: 10
B23: 4 | J23: 11
B24: 5 | J24: 12
B25: 6 | J25: 1
B26: 7 | J26: 2
B27: 8 | J27: 3
B28: 9 | J28: 4
B29: 10 | J29: 5
B30: 11 | J30: 6
B31: 12 | J31: 7
B32: 13 | J32: 8
B33: 14 | J33: 9
B34: 15 | J34: Total | K34: =SUM(K22:K33) -> 0 | L34: =SUM(L22:L33) -> 0 | M34: =SUM(M22:M33) -> 0 | N34: =SUM(N22:N33) -> 0 | O34: =SUM(O22:O33) -> 0 | P34: =SUM(P22:P33) -> 0 | Q34: =SUM(Q22:Q33) -> 0 | R34: =SUM(R22:R33) -> 0 | ... U34: =SUM(U22:U33) -> 0
B35: 16 | J35: Element/ Standard | K35: 1/3 | L35: 1/4 | M35: 1/5 | N35: 2/4 | O35: 2/5 | P35: 3/3 | Q35: 3/4 | R35: 4/2 | S35: 4/3 | T35: 4/4 | U35: 4/5
B36: 17
B37: 18
B38: 19 | J38: Calculations
B39: 20
B40: 21
B41: 22 | K41: Element 1 | L41: Element 2 | M41: Element 3 | N41: Element 4
...

Sheet Template (2)
C2: Element 1* | D2: Element 2* | E2: Element 3* | F2: Element 4 | H2: Key | K2: Month | L2: Element 1 Standard 1 Complaints | M2: Element 1 Standard 2 Service Recovery Missed | N2: Element 2 Standard 1 Unsigned Notes > 48 Hours | O2: Element 2 Standard 2 Exceptions | P2: Element 2 Standard 3 Non Standard Templates | Q2: Element 3 Standard 1 Encounters | R2: Element 3 Standard 2 Optician Caused Delays | S2: Element 4 Standard 1 TMS Modules Not Done | T2: TMS Modules Assigned
B3: Standard 1 | C3: =L16 -> #DIV/0! | D3: =N16 -> #DIV/0! | E3: =Q16 -> #DIV/0! | F3: =S16 -> #DIV/0! | I3: Unacceptable | K3: 10
B4: Standard 2 | C4: =M16 -> #DIV/0! | D4: =O16 -> #DIV/0! | E4: =R15 -> 0 | F4: =R34 -> 0 | I4: Minimally Successful | K4: 11
B5: Standard 3 | C5: =K34 -> 0 | D5: =P16 -> #DIV/0! | E5: =P34 -> 0 | F5: =S34 -> 0 | I5: Fully Successful | K5: 12
B6: Standard 4 | C6: =L34 -> 0 | D6: =N34 -> 0 | E6: =Q34 -> 0 | F6: =T34 -> 0 | I6: Exceptional | K6: 1
B7: Standard 5 | C7: =M34 -> 0 | D7: =O34 -> 0 | F7: =U34 -> 0 | I7: Not Fulfilled | K7: 2
B8: Standard Final | C8: =K42 -> #DIV/0! | D8: =L42 -> #DIV/0! | E8: =M42 -> #DIV/0! | F8: =N42 -> #DIV/0! | I8: Fulfilled | K8: 3
B9: Final | C9: =N44 -> #DIV/0! | I9: Outstanding | K9: 4
H10: * | I10: Critical Element | K10: 5
K11: 6
B12: Pay Period | C12: Regular | D12: OT | E12: LA | F12: LS | G12: Holiday | H12: Other | K12: 7
B13: 20 | I13: October | K13: 8
B14: 21 | K14: 9
B15: 22 | I15: November | K15: Total | L15: =SUM(L3:L14) -> 0 | M15: =SUM(M3:M14) -> 0 | N15: =SUM(N3:N14) -> 0 | O15: =SUM(O3:O14) -> 0 | P15: =SUM(P3:P14) -> 0 | Q15: =SUM(Q3:Q14) -> 0 | R15: =SUM(R3:R14) -> 0 | S15: =SUM(S3:S14) -> 0 | T15: =SUM(T3:T14) -> 0
B16: 23 | K16: % | L16: =SUM((L15/Q15)*100) -> #DIV/0! | M16: =SUM((1-((M15)/Q15))*100) -> #DIV/0! | N16: =SUM((1-(N15/Q15))*100) -> #DIV/0! | O16: =SUM(O15/Q15)*100 -> #DIV/0! | P16: =SUM((1-(P15/Q15))*100) -> #DIV/0! | Q16: =Q15/F47 -> #DIV/0! | S16: =SUM((1-(S15/T15))*100) -> #DIV/0!
B17: 24 | I17: December | K17: Element/ Standard | L17: 1/1 | M17: 1/2 | N17: 2/1 | O17: 2/2 | P17: 2/3 | Q17: 3/1 | R17: 3/2 | S17: 4/1
B18: 25
B19: 26 | J19: Month | K19: Element 1 Standard 3 Deescalations | L19: Element 1 Standard 4 Awards | M19: Element 1 Standard 5 Misc Vouluntary Service | N19: Element 2 Standard 4 Other staff assists | O19: Element 2 Standard 5 Process Improvement | P19: Element 3 Standard 3 Out of scope work | Q19: Element 3 Standard 4 Suggestions | R19: Element 4 Standard 2 Certifications Missing | S19: Element 4 Standard 3 New Certification | T19: Element 4 Standard 4 CE Credits | U19: Element 4 Standard 5 Voluntairy Extra Training
B20: 1 | I20: January
B21: 2
B22: 3 | I22: February | J22: 10
B23: 4 | J23: 11
B24: 5 | J24: 12
B25: 6 | J25: 1
B26: 7 | J26: 2
B27: 8 | J27: 3
B28: 9 | J28: 4
B29: 10 | J29: 5
B30: 11 | J30: 6
B31: 12 | J31: 7
B32: 13 | J32: 8
B33: 14 | J33: 9
B34: 15 | J34: Total | K34: =SUM(K22:K33) -> 0 | L34: =SUM(L22:L33) -> 0 | M34: =SUM(M22:M33) -> 0 | N34: =SUM(N22:N33) -> 0 | O34: =SUM(O22:O33) -> 0 | P34: =SUM(P22:P33) -> 0 | Q34: =SUM(Q22:Q33) -> 0 | R34: =SUM(R22:R33) -> 0 | ... U34: =SUM(U22:U33) -> 0
B35: 16 | J35: Element/ Standard | K35: 1/3 | L35: 1/4 | M35: 1/5 | N35: 2/4 | O35: 2/5 | P35: 3/3 | Q35: 3/4 | R35: 4/2 | S35: 4/3 | T35: 4/4 | U35: 4/5
B36: 17
B37: 18
B38: 19 | J38: Calculations
B39: 20
B40: 21
B41: 22 | K41: Element 1 | L41: Element 2 | M41: Element 3 | N41: Element 4
...

Sheet OT Calc
B1: Ryan | C1: Lara | D1: Andy | E1: Julie | F1: Paula | G1: TOTAL | I1: Year to Date Total
A2: October | B2: =SUM('6'!D13:D14) -> 1 | C2: =SUM('5'!D13:D14) -> 1.75 | D2: =SUM('1'!D13:D14) -> 0 | E2: =SUM('2'!D13:D14) -> 0.5 | F2: =SUM('4'!D13:D14) -> 1 | G2: =SUM(B2:F2) -> 4.25
A3: November | B3: =SUM('6'!D15:D16) -> 1.75 | C3: =SUM('5'!D15:D16) -> 2.75 | D3: =SUM('1'!D15:D16) -> 0.5 | E3: =SUM('2'!D15:D16) -> 2 | F3: =SUM('4'!D15:D16) -> 2.25 | G3: =SUM(B3:F3) -> 9.25 | I3: =SUM(G2:G13) -> 31.25
A4: December | B4: =SUM('6'!D17:D19) -> 0 | C4: =SUM('5'!D17:D19) -> 3.75 | D4: =SUM('1'!D17:D19) -> 0 | E4: =SUM('2'!D17:D19) -> 0 | F4: =SUM('4'!D17:D19) -> 2.25 | G4: =SUM(B4:F4) -> 6
A5: January | B5: =SUM('6'!D20:D21) -> 0 | C5: =SUM('5'!D20:D21) -> 3.5 | D5: =SUM('1'!D20:D21) -> 0 | E5: =SUM('2'!D20:D21) -> 0 | F5: =SUM('4'!D20:D21) -> 2.75 | G5: =SUM(B5:F5) -> 6.25
A6: February | B6: =SUM('6'!D22:D23) -> 0 | C6: =SUM('5'!D22:D23) -> 4 | D6: =SUM('1'!D22:D23) -> 0 | E6: =SUM('2'!D22:D23) -> 0 | F6: =SUM('4'!D22:D23) -> 1.5 | G6: =SUM(B6:F6) -> 5.5
A7: March | G7: =SUM(B7:F7) -> 0
A8: April | G8: =SUM(B8:F8) -> 0
A9: May | G9: =SUM(B9:F9) -> 0
A10: June | G10: =SUM(B10:F10) -> 0
A11: July | G11: =SUM(B11:F11) -> 0
A12: August | G12: =SUM(B12:F12) -> 0
A13: September | G13: =SUM(B13:F13) -> 0

Sheet CT Calc
B1: Ryan | C1: Lara | D1: Andy | E1: Julie | F1: Paula | G1: TOTAL
A2: October | G2: =SUM(B2:F2) -> 0
A3: November | G3: =SUM(B3:F3) -> 0
A4: December | G4: =SUM(B4:F4) -> 0
A5: January | G5: =SUM(B5:F5) -> 0
A6: February | G6: =SUM(B6:F6) -> 0
A7: March | G7: =SUM(B7:F7) -> 0
A8: April | G8: =SUM(B8:F8) -> 0
A9: May | G9: =SUM(B9:F9) -> 0
A10: June | G10: =SUM(B10:F10) -> 0
A11: July | G11: =SUM(B11:F11) -> 0
A12: August | G12: =SUM(B12:F12) -> 0
A13: September | G13: =SUM(B13:F13) -> 0
